reject 是用来抛出异常的，catch 才是用来处理异常的
类比传统的 try catch 写法，reject 就相当于 throw

然后 reject 是 Promise 的方法，而 catch 是 Promise 实例的方法：

let p = new Promise()
p.catch()
Promise.reject()

三种处理错误方法：
- 普通的js中 错误处理.
- promise 中的错误处理
- async 中的错误处理

在promise 中处理错误,我们通常也是去try catch,但是 `只能catch 到同步的错误`,如果是异步的,比如我们settimeout一下其实是catch不到的。
```
var promise = new Promise(function(resolve, reject){    
    setTimeout(function(){        
        throw new Error('test')     //异步的catch捕获不到，需要使用reject来抛错误
    }, 0)    
    resolve('ok'); //输出
});
promise
.then(function(value){ 
    console.log(value) 
    })    
.catch(()=> console.log('err'))
可以看到,只输出了ok,然后浏览器捕获的错误,catch并没有拿到.

```
`异步中，使用reject 来抛出错误`，不需要在then函数中throw，正常使用catch，也能捕捉到。

reject 会不停的返回到下一个,但是并不会被catch 到。所以需要在每个then函数中throw，这样在catch中能拿到。
- 在promise 中, 如果使用reject 错误,必须要`再每个then函数中throw 出去,不然在catch中无法拿到`；
- 其实我们不需要再次的throw，在promise正常catch 就好，比如在上面的异步中我们reject一下在最后就能catch到；
- 需要注意的一点就是:`promise 中的错误是不会影响外层的运行,window.onerror 也是无法检测到的`。

上面第一条和第二条有点疑惑，感觉很矛盾？？？


https://www.jianshu.com/p/fbefb5a45b09  （需要亲自实践）

https://github.com/scopsy/await-to-js